Workbook

Sheet SPD (2)
A1: SURAT PERJALANAN DINAS
A5: 1 | B5: Pejabat Pembuat Komitmen | E5: ='Rincian Biaya Perjadin'!G50 -> Dodi Oktavianto, S.E.
A8: 2 | B8: Nama Pegawai yang melaksanakan perjalanan dinas | E8: Dr. Ir. Selamat Muslimin, S.T., M.Kom.
B9: NIP | E9: ='Nominatif Format Baru'!C13 -> 197907222008011007
A12: 3 | B12: a. | C12: Pangkat dan golongan | D12: a. | E12: ='Nominatif Format Baru'!D13 -> Penata Tk. I/III/d
B13: b. | C13: Jabatan/Instansi | D13: b. | E13: Ketua Jurusan Teknik Elektro
B14: c | C14: Tingkat Biaya Perjalanan Dinas | D14: c | E14: B
A17: 4 | B17: Maksud perjalanan dinas | E17: Mengikuti kegiatan Indonesia-Swiss Partnership to Advance Indonesia's Renewable Energy Workforce: Launch of Renewable Energy Skills Development (RESD) Phase 2
A20: 5 | B20: Alat angkutan yang dipergunakan | E20: Pesawat
A23: 6 | B23: a. | C23: Tempat berangkat | D23: a. | E23: Palembang
B24: b. | C24: Tempat tujuan | D24: b. | E24: Jakarta
A27: 7 | B27: a. | C27: Lamanya Perjalanan Dinas | E27: =SPD!E27 -> 2 (Dua) Hari
B28: b. | C28: Tanggal Berangkat | E28: 20 Januari 2026
B29: c. | C29: Tanggal harus kembali/tiba ditempat baru *) | E29: 21 Januari 2026
A32: 8 | B32: Pengikut : Nama
B33: 1.
B34: 2.
A37: 9 | B37: Pembebanan Anggaran
B38: a. | C38: Instansi | E38: Politeknik Negeri Sriwijaya
B39: b. | C39: Akun
A42: 10 | B42: Keterangan lain-lain
B45: Tembusan lain-lain kepada : | D45: DIKELUARKAN DI | F45: : PALEMBANG
D46: PADA TANGGAL | F46: : 3 Februari 2026
D48: PEJABAT PEMBUAT KOMITMEN
D53: ='Rincian Biaya Perjadin'!G50 -> Dodi Oktavianto, S.E.
D54: NIP. 197810032008101001
A56: SURAT PERJALANAN DINAS
A60: 1 | B60: Pejabat Pembuat Komitmen | E60: =E5 -> Dodi Oktavianto, S.E.
A63: 2 | B63: Nama Pegawai yang melaksanakan perjalanan dinas | E63: Prof. Dr. Ir. Rusdianasari, M.Si.
B64: NIP | E64: ='Nominatif Format Baru'!C14 -> 196711191993032003
A67: 3 | B67: a. | C67: Pangkat dan golongan | D67: a. | E67: Pembina Utama/IV/e
B68: b. | C68: Jabatan/Instansi | D68: b. | E68: KPS. Magister Terapan
B69: c | C69: Tingkat Biaya Perjalanan Dinas | D69: c | E69: A
A72: 4 | B72: Maksud perjalanan dinas | E72: =E17 -> Mengikuti kegiatan Indonesia-Swiss Partnership to Advance Indonesia's Renewable Energy Workforce: Launch of Renewable Energy Skills Development (RESD) Phase 2
A75: 5 | B75: Alat angkutan yang dipergunakan | E75: Pesawat
A78: 6 | B78: a. | C78: Tempat berangkat | D78: a. | E78: Palembang
B79: b. | C79: Tempat tujuan | D79: b. | E79: =E24 -> Jakarta
A82: 7 | B82: a. | C82: Lamanya Perjalanan Dinas | E82: =E27 -> 2 (Dua) Hari
B83: b. | C83: Tanggal Berangkat | E83: 20 Januari 2026
B84: c. | C84: Tanggal harus kembali/tiba ditempat baru *) | E84: 21 Januari 2026
...

Sheet SPD
A1: SURAT PERJALANAN DINAS
A5: 1 | B5: Pejabat Pembuat Komitmen | E5: ='Rincian Biaya Perjadin'!G50 -> Dodi Oktavianto, S.E.
A8: 2 | B8: Nama Pegawai yang melaksanakan perjalanan dinas | E8: Ir. Irawan Rusnadi, M.T.
B9: NIP | E9: ='Nominatif Format Baru'!C11 -> 196702021994031004
A12: 3 | B12: a. | C12: Pangkat dan golongan | D12: a. | E12: ='Nominatif Format Baru'!D11 -> Pembina Utama Muda/IV/c
B13: b. | C13: Jabatan/Instansi | D13: b. | E13: Direktur
B14: c | C14: Tingkat Biaya Perjalanan Dinas | D14: c | E14: A
A17: 4 | B17: Maksud perjalanan dinas | E17: Mengikuti kegiatan Indonesia-Swiss Partnership to Advance Indonesia's Renewable Energy Workforce: Launch of Renewable Energy Skills Development (RESD) Phase 2
A20: 5 | B20: Alat angkutan yang dipergunakan | E20: Pesawat
A23: 6 | B23: a. | C23: Tempat berangkat | D23: a. | E23: Palembang
B24: b. | C24: Tempat tujuan | D24: b. | E24: Jakarta
A27: 7 | B27: a. | C27: Lamanya Perjalanan Dinas | E27: 2 (Dua) Hari
B28: b. | C28: Tanggal Berangkat | E28: 20 Januari 2026
B29: c. | C29: Tanggal harus kembali/tiba ditempat baru *) | E29: 21 Januari 2026
A32: 8 | B32: Pengikut : Nama
B33: 1.
B34: 2.
A37: 9 | B37: Pembebanan Anggaran
B38: a. | C38: Instansi | E38: Politeknik Negeri Sriwijaya
B39: b. | C39: Akun
A42: 10 | B42: Keterangan lain-lain
B45: Tembusan lain-lain kepada : | D45: DIKELUARKAN DI | F45: : PALEMBANG
D46: PADA TANGGAL | F46: : 3 Februari 2026
D48: PEJABAT PEMBUAT KOMITMEN
D53: ='Rincian Biaya Perjadin'!G50 -> Dodi Oktavianto, S.E.
D54: NIP. 197810032008101001
A59: SURAT PERJALANAN DINAS
A63: 1 | B63: Pejabat Pembuat Komitmen | E63: =E5 -> Dodi Oktavianto, S.E.
A66: 2 | B66: Nama Pegawai yang melaksanakan perjalanan dinas | E66: Dr. Irma Salamah, S.T.M.TI.
B67: NIP | E67: ='Nominatif Format Baru'!C12 -> 197410221998022001
A70: 3 | B70: a. | C70: Pangkat dan golongan | D70: a. | E70: ='Nominatif Format Baru'!D12 -> Pembina Tk. I/IV/b
B71: b. | C71: Jabatan/Instansi | D71: b. | E71: Wakil Direktur IV
B72: c | C72: Tingkat Biaya Perjalanan Dinas | D72: c | E72: A
A75: 4 | B75: Maksud perjalanan dinas | E75: =E17 -> Mengikuti kegiatan Indonesia-Swiss Partnership to Advance Indonesia's Renewable Energy Workforce: Launch of Renewable Energy Skills Development (RESD) Phase 2
A78: 5 | B78: Alat angkutan yang dipergunakan | E78: Pesawat
A81: 6 | B81: a. | C81: Tempat berangkat | D81: a. | E81: Palembang
B82: b. | C82: Tempat tujuan | D82: b. | E82: =E24 -> Jakarta
A85: 7 | B85: a. | C85: Lamanya Perjalanan Dinas | E85: =E27 -> 2 (Dua) Hari
B86: b. | C86: Tanggal Berangkat | E86: 20 Januari 2026
B87: c. | C87: Tanggal harus kembali/tiba ditempat baru *) | E87: 21 Januari 2026
...

Sheet Rincian Biaya Perjadin (2)
A1: RINCIAN BIAYA PERJALANAN DINAS
B3: Lampiran SPPD Nomor | H3: : | I3: /SPPD/BLU/2025
B4: Tanggal | H4: : | I4: 15 Januari 2026
A8: NO. | B8: Perincian Biaya | H8: Jumlah | J8: Keterangan
A11: 1 | B11: Uang Harian 2 (Dua) hari @ Rp 530.000,- | H11: Rp. | I11: =2*530000 -> 1060000
A12: 2 | B12: Tiket Palembang-Jakarta (PP) | H12: Rp. | I12: 2529207
A13: 3 | B13: Penginapan | H13: Rp.
A14: 4 | B14: Transport Darat/taksi (PP) | H14: Rp.
A15: 5 | B15: Transport Lokal/taksi (PP) | H15: Rp.
H17: Rp. | I17: =SUM(I11:I14) -> 3589207
B19: Terbilang : | D19: =[1]!terbilang(I17,4,"rupiah,-") -> Tiga juta lima ratus delapan puluh sembilan ribu dua ratus tujuh rupiah,-
H22: Palembang, 15 Januari 2026
B23: Telah dibayar sejumlah | H23: Telah menerima jumlah uang sebesar
B24: Rp. | C24: =I17 -> 3589207 | D24: ,- | H24: Rp. | I24: =I17 -> 3589207 | J24: ,-
H25: =[1]!terbilang(I24,4,"rupiah,-") -> Tiga juta lima ratus delapan puluh sembilan ribu dua ratus tujuh rupiah,-
B29: Bendahara Pengeluaran | J29: Yang menerima,
B33: Nofitri Kurniawati, S.E. | J33: ='SPD (2)'!E8 -> Dr. Ir. Selamat Muslimin, S.T., M.Kom.
B34: NIP. 197011242001122001 | J34: NIP | K34: ='SPD (2)'!E9 -> 197907222008011007
B37: PERHITUNGAN SPPD RAMPUNG
B40: Ditetapkan sejumlah | E40: : | G40: =C24 -> 3589207 | H40: ,-
B41: Yang telah dibayar semula | E41: : | G41: =I24 -> 3589207 | H41: ,-
B42: Sisa kurang / lebih | E42: : | G42: NIHIL | H42: ,--
G45: Pejabat Pembuat Komitmen
G50: Dodi Oktavianto, S.E.
G51: NIP. 197810032008101001
I53: Beban MAK | K53: :
I54: Bukti Kas No. | K54: :
I55: Tahun Anggaran | K55: : 2025
A58: K U I T A N S I
B61: Sudah Terima dari | E61: : | F61: Bendaharawan Politeknik Negeri Sriwijaya
B62: Uang Sebesar | E62: : | F62: Rp. | G62: =I17 -> 3589207 | H62: ,-
B63: Untuk Pembayaran | E63: : | F63: Biaya perjalanan dinas
B64: Berdasarkan SPPD | E64: : | F64: Direktur Politeknik Negeri Sriwijaya
B65: Nomor | E65: : | F65: /SPPD/BLU/2025
B66: Tanggal | E66: : | F66: =I4 -> 15 Januari 2026
B67: Untuk perjalanan dinas dari | E67: : | F67: Palembang-Jakarta
B68: Terbilang | E68: : | F68: =[1]!terbilang(G62,4,"rupiah,-") -> Tiga juta lima ratus delapan puluh sembilan ribu dua ratus tujuh rupiah,-
B72: Dibukukan tanggal | J72: =H22 -> Palembang, 15 Januari 2026
B73: Bendahara Pengeluaran | J73: Yang menerima,
B78: Nofitri Kurniawati, S.E. | J78: =J33 -> Dr. Ir. Selamat Muslimin, S.T., M.Kom.
...

Sheet Rincian Biaya Perjadin
A1: RINCIAN BIAYA PERJALANAN DINAS
B3: Lampiran SPPD Nomor | H3: : | I3: /SPPD/BLU/2025
B4: Tanggal | H4: : | I4: 15 Januari 2026
A8: NO. | B8: Perincian Biaya | H8: Jumlah | J8: Keterangan
A11: 1 | B11: Uang Harian 2 (Dua) hari @ Rp 530.000,- | H11: Rp. | I11: =2*530000 -> 1060000
A12: 2 | B12: Tiket Palembang-Jakarta (PP) | H12: Rp. | I12: 2529207
A13: 3 | B13: Penginapan | H13: Rp. | I13: 1350928
A14: 4 | B14: Transport Darat/taksi (PP) | H14: Rp. | I14: 221000
A15: 5 | B15: Transport Lokal/taksi (PP) | H15: Rp.
H17: Rp. | I17: =SUM(I11:I16) -> 5161135
B19: Terbilang : | D19: =[1]!terbilang(I17,4,"rupiah,-") -> Lima juta seratus enam puluh satu ribu seratus tiga puluh lima rupiah,-
H22: Palembang, 15 Januari 2026
B23: Telah dibayar sejumlah | H23: Telah menerima jumlah uang sebesar
B24: Rp. | C24: =I17 -> 5161135 | D24: ,- | H24: Rp. | I24: =I17 -> 5161135 | J24: ,-
H25: =[1]!terbilang(I24,4,"rupiah,-") -> Lima juta seratus enam puluh satu ribu seratus tiga puluh lima rupiah,-
B29: Bendahara Pengeluaran | J29: Yang menerima,
B33: Nofitri Kurniawati, S.E. | J33: =SPD!E8 -> Ir. Irawan Rusnadi, M.T.
B34: NIP. 197011242001122001 | J34: NIP | K34: ='Nominatif Format Baru'!C11 -> 196702021994031004
B37: PERHITUNGAN SPPD RAMPUNG
B40: Ditetapkan sejumlah | E40: : | G40: =C24 -> 5161135 | H40: ,-
B41: Yang telah dibayar semula | E41: : | G41: =I24 -> 5161135 | H41: ,-
B42: Sisa kurang / lebih | E42: : | G42: NIHIL | H42: ,--
G45: Pejabat Pembuat Komitmen
G50: Dodi Oktavianto, S.E.
G51: NIP. 197810032008101001
I53: Beban MAK | K53: :
I54: Bukti Kas No. | K54: :
I55: Tahun Anggaran | K55: : 2025
A58: K U I T A N S I
B61: Sudah Terima dari | E61: : | F61: Bendaharawan Politeknik Negeri Sriwijaya
B62: Uang Sebesar | E62: : | F62: Rp. | G62: =I17 -> 5161135 | H62: ,-
B63: Untuk Pembayaran | E63: : | F63: Biaya perjalanan dinas
B64: Berdasarkan SPPD | E64: : | F64: Direktur Politeknik Negeri Sriwijaya
B65: Nomor | E65: : | F65: /SPPD/BLU/2025
B66: Tanggal | E66: : | F66: =I4 -> 15 Januari 2026
B67: Untuk perjalanan dinas dari | E67: : | F67: Palembang-Jakarta
B68: Terbilang | E68: : | F68: =[1]!terbilang(G62,4,"rupiah,-") -> Lima juta seratus enam puluh satu ribu seratus tiga puluh lima rupiah,-
B72: Dibukukan tanggal | J72: =H22 -> Palembang, 15 Januari 2026
B73: Bendahara Pengeluaran | J73: Yang menerima,
B78: Nofitri Kurniawati, S.E. | J78: =J33 -> Ir. Irawan Rusnadi, M.T.
...

Sheet Surat Pernyataan (4)
H1: KEMENTERIAN PENDIDIKAN,KEBUDAYAAN,
H2: RISET, DAN TEKNOLOGI
H3: POLITEKNIK NEGERI SRIWIJAYA
H4: Jalan Srijaya Negara Bukit Besar – Palembang 30139
H5: Telp. 0711-353414 Fax. 0711-355918
H6: Laman : http://polsri.ac.id, Pos El : info@polsri.ac.id
A9: SURAT PERNYATAAN
B13: Yang bertanda tangan di bawah ini :
B15: Nama | E15: : | F15: ='SPD (2)'!E63 -> Prof. Dr. Ir. Rusdianasari, M.Si.
B16: NIP | E16: : | F16: ='SPD (2)'!E64 -> 196711191993032003
B17: Jabatan | E17: : | F17: KPS. Magister Terapan
B19: ='Surat Pernyataan'!B19:K19 -> Berdasarkan Surat Tugas tanggal 15 Januari 2026 Nomor: 0361/PL6.4.2/ST/2025 dengan ini kami menyatakan dengan sesungguhnya bahwa :
B21: 1. | C21: Bukti-bukti (Tiket / bukti transportasi, Boarding Pass, Kwitansi, Hotel bill / tagihan hotel dan sebagainya ) yang dilampirkan dalam rangka melakukan perjalanan dinas adalah bukti-bukti asli dan benar yang dikeluarkan oleh perusahaan / instansi yang berwenang untuk menerbitkan bukti-bukti tesebut.
B23: 2. | C23: Apabila dikemudian hari terdapat kesalahan atau temuan dari aparat pengawasan fungsional, kami bersedia untuk mempertanggungjawabkannya
B25: Demikian pernyataan ini kami buat dengan sebenarnya, untuk dipertanggungjawabkan sebagaimana mestinya.
B27: Mengetahui/Menyetujui | I27: Palembang, | K27: 22 Januari 2026
B28: an.Kuasa Pengguna Anggaran | I28: Yang melakukan Perjalanan dinas,
B29: Pejabat Pembuat Komitmen
B32: ='Rincian Biaya Perjadin'!G50 -> Dodi Oktavianto, S.E. | I32: =F15 -> Prof. Dr. Ir. Rusdianasari, M.Si.
B33: NIP. 197810032008101001 | I33: NIP | J33: =F16 -> 196711191993032003

Sheet Surat Pernyataan (3)
H1: KEMENTERIAN PENDIDIKAN,KEBUDAYAAN,
H2: RISET, DAN TEKNOLOGI
H3: POLITEKNIK NEGERI SRIWIJAYA
H4: Jalan Srijaya Negara Bukit Besar – Palembang 30139
H5: Telp. 0711-353414 Fax. 0711-355918
H6: Laman : http://polsri.ac.id, Pos El : info@polsri.ac.id
A9: SURAT PERNYATAAN
B13: Yang bertanda tangan di bawah ini :
B15: Nama | E15: : | F15: ='Rincian Biaya Perjadin (2)'!J33 -> Dr. Ir. Selamat Muslimin, S.T., M.Kom.
B16: NIP | E16: : | F16: ='Rincian Biaya Perjadin (2)'!K34 -> 197907222008011007
B17: Jabatan | E17: : | F17: Ketua Jurusan Teknik Elektro
B19: ='Surat Pernyataan'!B19:K19 -> Berdasarkan Surat Tugas tanggal 15 Januari 2026 Nomor: 0361/PL6.4.2/ST/2025 dengan ini kami menyatakan dengan sesungguhnya bahwa :
B21: 1. | C21: Bukti-bukti (Tiket / bukti transportasi, Boarding Pass, Kwitansi, Hotel bill / tagihan hotel dan sebagainya ) yang dilampirkan dalam rangka melakukan perjalanan dinas adalah bukti-bukti asli dan benar yang dikeluarkan oleh perusahaan / instansi yang berwenang untuk menerbitkan bukti-bukti tesebut.
B23: 2. | C23: Apabila dikemudian hari terdapat kesalahan atau temuan dari aparat pengawasan fungsional, kami bersedia untuk mempertanggungjawabkannya
B25: Demikian pernyataan ini kami buat dengan sebenarnya, untuk dipertanggungjawabkan sebagaimana mestinya.
B27: Mengetahui/Menyetujui | I27: Palembang, | K27: 22 Januari 2026
B28: an.Kuasa Pengguna Anggaran | I28: Yang melakukan Perjalanan dinas,
B29: Pejabat Pembuat Komitmen
B32: ='Rincian Biaya Perjadin'!G50 -> Dodi Oktavianto, S.E. | I32: =F15 -> Dr. Ir. Selamat Muslimin, S.T., M.Kom.
B33: NIP. 197810032008101001 | I33: NIP | J33: =F16 -> 197907222008011007

Sheet Surat Pernyataan (2)
H1: KEMENTERIAN PENDIDIKAN,KEBUDAYAAN,
H2: RISET, DAN TEKNOLOGI
H3: POLITEKNIK NEGERI SRIWIJAYA
H4: Jalan Srijaya Negara Bukit Besar – Palembang 30139
H5: Telp. 0711-353414 Fax. 0711-355918
H6: Laman : http://polsri.ac.id, Pos El : info@polsri.ac.id
A9: SURAT PERNYATAAN
B13: Yang bertanda tangan di bawah ini :
B15: Nama | E15: : | F15: =SPD!E66 -> Dr. Irma Salamah, S.T.M.TI.
B16: NIP | E16: : | F16: =SPD!E67 -> 197410221998022001
B17: Jabatan | E17: : | F17: =SPD!E71 -> Wakil Direktur IV
B19: ='Surat Pernyataan'!B19:K19 -> Berdasarkan Surat Tugas tanggal 15 Januari 2026 Nomor: 0361/PL6.4.2/ST/2025 dengan ini kami menyatakan dengan sesungguhnya bahwa :
B21: 1. | C21: Bukti-bukti (Tiket / bukti transportasi, Boarding Pass, Kwitansi, Hotel bill / tagihan hotel dan sebagainya ) yang dilampirkan dalam rangka melakukan perjalanan dinas adalah bukti-bukti asli dan benar yang dikeluarkan oleh perusahaan / instansi yang berwenang untuk menerbitkan bukti-bukti tesebut.
B23: 2. | C23: Apabila dikemudian hari terdapat kesalahan atau temuan dari aparat pengawasan fungsional, kami bersedia untuk mempertanggungjawabkannya
B25: Demikian pernyataan ini kami buat dengan sebenarnya, untuk dipertanggungjawabkan sebagaimana mestinya.
B27: Mengetahui/Menyetujui | I27: Palembang, | K27: 22 Januari 2026
B28: an.Kuasa Pengguna Anggaran | I28: Yang melakukan Perjalanan dinas,
B29: Pejabat Pembuat Komitmen
B32: ='Rincian Biaya Perjadin'!G50 -> Dodi Oktavianto, S.E. | I32: =F15 -> Dr. Irma Salamah, S.T.M.TI.
B33: NIP. 197810032008101001 | I33: NIP | J33: =F16 -> 197410221998022001

Sheet Surat Pernyataan
H1: KEMENTERIAN PENDIDIKAN,KEBUDAYAAN,
H2: RISET, DAN TEKNOLOGI
H3: POLITEKNIK NEGERI SRIWIJAYA
H4: Jalan Srijaya Negara Bukit Besar – Palembang 30139
H5: Telp. 0711-353414 Fax. 0711-355918
H6: Laman : http://polsri.ac.id, Pos El : info@polsri.ac.id
A9: SURAT PERNYATAAN
B13: Yang bertanda tangan di bawah ini :
B15: Nama | E15: : | F15: =SPD!E8 -> Ir. Irawan Rusnadi, M.T.
B16: NIP | E16: : | F16: =SPD!E9 -> 196702021994031004
B17: Jabatan | E17: : | F17: =SPD!E13 -> Direktur
B19: Berdasarkan Surat Tugas tanggal 15 Januari 2026 Nomor: 0361/PL6.4.2/ST/2025 dengan ini kami menyatakan dengan sesungguhnya bahwa :
B21: 1. | C21: Bukti-bukti (Tiket / bukti transportasi, Boarding Pass, Kwitansi, Hotel bill / tagihan hotel dan sebagainya ) yang dilampirkan dalam rangka melakukan perjalanan dinas adalah bukti-bukti asli dan benar yang dikeluarkan oleh perusahaan / instansi yang berwenang untuk menerbitkan bukti-bukti tesebut.
B23: 2. | C23: Apabila dikemudian hari terdapat kesalahan atau temuan dari aparat pengawasan fungsional, kami bersedia untuk mempertanggungjawabkannya
B25: Demikian pernyataan ini kami buat dengan sebenarnya, untuk dipertanggungjawabkan sebagaimana mestinya.
B27: Mengetahui/Menyetujui | I27: Palembang, | K27: 22 Januari 2026
B28: an.Kuasa Pengguna Anggaran | I28: Yang melakukan Perjalanan dinas,
B29: Pejabat Pembuat Komitmen
B32: ='Rincian Biaya Perjadin'!G50 -> Dodi Oktavianto, S.E. | I32: =F15 -> Ir. Irawan Rusnadi, M.T.
B33: NIP. 197810032008101001 | I33: NIP | J33: =F16 -> 196702021994031004

Sheet Pak darmo format baru
A3: DAFTAR KONTROL PEMBAYARAN
A4: BIAYA PERJALANAN DINAS TIKET DAN PENGINAPAN
A5: MAK : 7732.DBA.001.053.C.525115(000039)
A7: No. | B7: Nama | C7: NIP | D7: Pangkat / Gol | E7: Tujuan | F7: Tanggal Berangkat | G7: Lama Perjalanan Dinas | H7: Biaya Perjalanan Dinas | P7: Rekening | Q7: Tanda tangan
H8: Tiket | I8: Transport Darat | J8: Transport Lokal | K8: Transport | L8: Penginapan | M8: Uang Harian | N8: Uang Representasi | O8: Jumlah
A10: 1 | B10: ='Nominatif Format Baru'!B11 -> Ir. Irawan Rusnadi, M.T. ST No. 0361/PL6.4.2/ST/2026 Tanggal 15 Januari 2026 | C10: ='Nominatif Format Baru'!C11 -> 196702021994031004 | D10: ='Nominatif Format Baru'!D11 -> Pembina Utama Muda/IV/c | E10: ='Nominatif Format Baru'!E11 -> Jakarta | F10: ='Nominatif Format Baru'!F11 -> 20-21/01/2026 | G10: ='Nominatif Format Baru'!G11 -> 2 Hari | H10: ='Nominatif Format Baru'!H11 -> 2529207 | L10: ='Nominatif Format Baru'!L11 -> 1350928 | O10: =SUM(H10:N10) -> 3880135 | P10: 575901009468538 (Darmawan)
A11: 2 | B11: ='Nominatif Format Baru'!B12 -> Dr. Irma Salamah, S.T., M.TI. ST No. 0361/PL6.4.2/ST/2026 Tanggal 15 Januari 2026 | C11: ='Nominatif Format Baru'!C12 -> 197410221998022001 | D11: ='Nominatif Format Baru'!D12 -> Pembina Tk. I/IV/b | E11: ='Nominatif Format Baru'!E12 -> Jakarta | F11: ='Nominatif Format Baru'!F12 -> 20-21/01/2026 | G11: ='Nominatif Format Baru'!G12 -> 2 Hari | H11: ='Nominatif Format Baru'!H12 -> 2429270 | L11: ='Nominatif Format Baru'!L12 -> 1350928 | O11: =SUM(H11:N11) -> 3780198 | P11: 575901009468538 (Darmawan)
A12: 3 | B12: ='Nominatif Format Baru'!B13 -> Dr. Selamat Muslimin, S.T., M.Kom ST No. 0361/PL6.4.2/ST/2026 Tanggal 15 Januari 2026 | C12: ='Nominatif Format Baru'!C13 -> 197907222008011007 | D12: ='Nominatif Format Baru'!D13 -> Penata Tk. I/III/d | E12: ='Nominatif Format Baru'!E13 -> Jakarta | F12: ='Nominatif Format Baru'!F13 -> 20-21/01/2026 | G12: ='Nominatif Format Baru'!G13 -> 2 Hari | H12: ='Nominatif Format Baru'!H13 -> 2529207 | O12: =SUM(H12:N12) -> 2529207 | P12: 575901009468538 (Darmawan)
A13: 4 | B13: ='Nominatif Format Baru'!B14 -> Prof. Dr. Ir. Rusdianasari, M.Si ST No. 0361/PL6.4.2/ST/2026 Tanggal 15 Januari 2026 | C13: ='Nominatif Format Baru'!C14 -> 196711191993032003 | D13: ='Nominatif Format Baru'!D14 -> Pembina Utama/IV/e | E13: ='Nominatif Format Baru'!E14 -> Jakarta | F13: ='Nominatif Format Baru'!F14 -> 20-21/01/2026 | G13: ='Nominatif Format Baru'!G14 -> 2 Hari | H13: ='Nominatif Format Baru'!H14 -> 2529207 | O13: =SUM(H13:N13) -> 2529207 | P13: 575901009468538 (Darmawan)
A14: J U M L A H | K14: =SUM(K10:K10) -> 0 | L14: =SUM(L10:L13) -> 2701856 | M14: =SUM(M10:M10) -> 0 | N14: =SUM(N10:N10) -> 0 | O14: =SUM(O10:O13) -> 12718747
A15: TERBILANG | F15: =[1]!terbilang(O14,4,"Rupiah,-") -> Dua belas juta tujuh ratus delapan belas ribu tujuh ratus empat puluh tujuh rupiah,-
B18: Mengetahui, | O18: Palembang, 3 Februari 2026
B19: Yang Membayar,
B24: Asmanidar, S.E. | O24: Darmawan, A.Md.
B25: NIP. 197204051994032001 | O25: NIP. 198510242009121004

Sheet format baru bersangkutan
A3: DAFTAR KONTROL PEMBAYARAN
A4: BIAYA PERJALANAN DINAS UANG HARIAN DAN TRANSPORT LOKAL
A5: MAK : 7732.DBA.001.053.C.525115(000039)
A7: No. | B7: Nama | C7: NIP | D7: Pangkat / Gol | E7: Tujuan | F7: Tanggal Berangkat | G7: Lama Perjalanan Dinas | H7: Biaya Perjalanan Dinas | P7: Rekening | Q7: Tanda tangan
H8: Tiket | I8: Transport Darat | J8: Transport Lokal | K8: Transport | L8: Penginapan | M8: Uang Harian | N8: Uang Representasi | O8: Jumlah
A10: 1 | B10: ='Nominatif Format Baru'!B11 -> Ir. Irawan Rusnadi, M.T. ST No. 0361/PL6.4.2/ST/2026 Tanggal 15 Januari 2026 | C10: ='Nominatif Format Baru'!C11 -> 196702021994031004 | D10: ='Nominatif Format Baru'!D11 -> Pembina Utama Muda/IV/c | E10: ='Nominatif Format Baru'!E11 -> Jakarta | F10: ='Nominatif Format Baru'!F11 -> 20-21/01/2026 | G10: ='Nominatif Format Baru'!G11 -> 2 Hari | I10: ='Nominatif Format Baru'!I11 -> 221000 | M10: ='Nominatif Format Baru'!M11 -> 1060000 | O10: =SUM(H10:N10) -> 1281000 | P10: 9000007239669
A11: 2 | B11: ='Nominatif Format Baru'!B12 -> Dr. Irma Salamah, S.T., M.TI. ST No. 0361/PL6.4.2/ST/2026 Tanggal 15 Januari 2026 | C11: ='Nominatif Format Baru'!C12 -> 197410221998022001 | D11: ='Nominatif Format Baru'!D12 -> Pembina Tk. I/IV/b | E11: ='Nominatif Format Baru'!E12 -> Jakarta | F11: ='Nominatif Format Baru'!F12 -> 20-21/01/2026 | G11: ='Nominatif Format Baru'!G12 -> 2 Hari | M11: ='Nominatif Format Baru'!M12 -> 1060000 | O11: =SUM(H11:N11) -> 1060000 | P11: 1130004025262
A12: 3 | B12: ='Nominatif Format Baru'!B13 -> Dr. Selamat Muslimin, S.T., M.Kom ST No. 0361/PL6.4.2/ST/2026 Tanggal 15 Januari 2026 | C12: ='Nominatif Format Baru'!C13 -> 197907222008011007 | D12: ='Nominatif Format Baru'!D13 -> Penata Tk. I/III/d | E12: ='Nominatif Format Baru'!E13 -> Jakarta | F12: ='Nominatif Format Baru'!F13 -> 20-21/01/2026 | G12: ='Nominatif Format Baru'!G13 -> 2 Hari | M12: ='Nominatif Format Baru'!M13 -> 1060000 | O12: =SUM(H12:N12) -> 1060000 | P12: 1130006996569
A13: 4 | B13: ='Nominatif Format Baru'!B14 -> Prof. Dr. Ir. Rusdianasari, M.Si ST No. 0361/PL6.4.2/ST/2026 Tanggal 15 Januari 2026 | C13: ='Nominatif Format Baru'!C14 -> 196711191993032003 | D13: ='Nominatif Format Baru'!D14 -> Pembina Utama/IV/e | E13: ='Nominatif Format Baru'!E14 -> Jakarta | F13: ='Nominatif Format Baru'!F14 -> 20-21/01/2026 | G13: ='Nominatif Format Baru'!G14 -> 2 Hari | I13: ='Nominatif Format Baru'!I14 -> 288000 | M13: ='Nominatif Format Baru'!M14 -> 1060000 | O13: =SUM(H13:N13) -> 1348000 | P13: 1130007386133
A14: J U M L A H | K14: =SUM(K10:K10) -> 0 | L14: =SUM(L10:L10) -> 0 | M14: =SUM(M10:M13) -> 4240000 | N14: =SUM(N10:N10) -> 0 | O14: =SUM(O10:O13) -> 4749000
A15: TERBILANG | F15: =[1]!terbilang(O14,4,"Rupiah,-") -> Empat juta tujuh ratus empat puluh sembilan ribu rupiah,-
B18: Mengetahui, | O18: Palembang, 3 Februari 2026
B19: yang Membayar, | O19: Yang Menerima,
B24: Asmanidar, S.E.
B25: NIP. 197204051994032001 | O25: NIP.

Sheet Nominatif Format Baru
O1: No : 02
O2: Tanggal : 3 Februari 2026
A5: DAFTAR NOMINATIF PEMBAYARAN PERJALANAN DINAS
A6: MAK : 7732.DBA.001.053.C.525115(000039)
A8: No. | B8: Nama | C8: NIP | D8: Pangkat / Gol | E8: Tujuan | F8: Tanggal Berangkat | G8: Lama Perjalanan Dinas | K8: Biaya Perjalanan Dinas | P8: Rekening | Q8: Tanda tangan
H9: Tiket | I9: Transport Darat | J9: Transport Lokal | K9: Transport | L9: Penginapan | M9: Uang Harian | N9: Uang Representasi | O9: Jumlah
A11: 1 | B11: Ir. Irawan Rusnadi, M.T. ST No. 0361/PL6.4.2/ST/2026 Tanggal 15 Januari 2026 | C11: 196702021994031004 | D11: Pembina Utama Muda/IV/c | E11: Jakarta | F11: 20-21/01/2026 | G11: 2 Hari | H11: ='Rincian Biaya Perjadin'!I12 -> 2529207 | I11: ='Rincian Biaya Perjadin'!I14 -> 221000 | K11: =SUM(H11:J11) -> 2750207 | L11: ='Rincian Biaya Perjadin'!I13 -> 1350928 | M11: ='Rincian Biaya Perjadin'!I11 -> 1060000 | O11: =SUM(K11:N11) -> 5161135
A12: 2 | B12: Dr. Irma Salamah, S.T., M.TI. ST No. 0361/PL6.4.2/ST/2026 Tanggal 15 Januari 2026 | C12: 197410221998022001 | D12: Pembina Tk. I/IV/b | E12: Jakarta | F12: 20-21/01/2026 | G12: 2 Hari | H12: ='Rincian Biaya Perjadin'!I102 -> 2429270 | K12: =SUM(H12:J12) -> 2429270 | L12: ='Rincian Biaya Perjadin'!I103 -> 1350928 | M12: ='Rincian Biaya Perjadin'!I101 -> 1060000 | O12: =SUM(K12:N12) -> 4840198
A13: 3 | B13: Dr. Selamat Muslimin, S.T., M.Kom ST No. 0361/PL6.4.2/ST/2026 Tanggal 15 Januari 2026 | C13: 197907222008011007 | D13: Penata Tk. I/III/d | E13: Jakarta | F13: 20-21/01/2026 | G13: 2 Hari | H13: ='Rincian Biaya Perjadin (2)'!I12 -> 2529207 | K13: =SUM(H13:J13) -> 2529207 | M13: ='Rincian Biaya Perjadin (2)'!I11 -> 1060000 | O13: =SUM(K13:N13) -> 3589207
A14: 4 | B14: Prof. Dr. Ir. Rusdianasari, M.Si ST No. 0361/PL6.4.2/ST/2026 Tanggal 15 Januari 2026 | C14: 196711191993032003 | D14: Pembina Utama/IV/e | E14: Jakarta | F14: 20-21/01/2026 | G14: 2 Hari | H14: ='Rincian Biaya Perjadin (2)'!I102 -> 2529207 | I14: ='Rincian Biaya Perjadin (2)'!I104 -> 288000 | K14: =SUM(H14:J14) -> 2817207 | M14: ='Rincian Biaya Perjadin (2)'!I101 -> 1060000 | O14: =SUM(K14:N14) -> 3877207
K15: =SUM(K11:K14) -> 10525891 | L15: =SUM(L11:L14) -> 2701856 | M15: =SUM(M11:M14) -> 4240000 | N15: =SUM(N11:N11) -> 0 | O15: =SUM(O11:O14) -> 17467747
A16: TERBILANG | F16: =[1]!terbilang(O15)&" Rupiah" -> Tujuh belas juta empat ratus enam puluh tujuh ribu tujuh ratus empat puluh tujuh Rupiah
B19: Mengetahui, | N19: Palembang, 3 Februari 2026
B20: Pejabat Pembuat Komitmen,
B25: Dodi Oktavianto, S.E. | N25: Asmanidar, S.E.
B26: NIP. 197810032008101001 | N26: NIP. 197204051994032001

Sheet TTD
G4: Palembang
G5: 20 Januari 2026
G6: Jakarta
F9: Dodi Oktavianto, S.E.
F10: NIP. 197810032008101001
A12: I. | C12: Jakarta | G12: Jakarta
C13: 20 Januari 2026 | G13: Palembang
H14: 21 Januari 2026
B15: Kepala | C15: Perencanaan, Keuangan & Umum | G15: Kepala | H15: Perencanaan, Keuangan
H16: & Umum
B20: Ni Ketut Nurhayati, S.E., MAP | F20: Ni Ketut Nurhayati, S.E., MAP
B21: 197205292002122001 | F21: 197205292002122001
B22: Kepala | C22: : | D22: Direktur Protel Multi Energy | G22: Kepala | H22: =D22 -> Direktur Protel Multi Energy
B25: Komarudin, S.T | G25: =B25 -> Komarudin, S.T
B26: 196805141993031002 | G26: =B26 -> 196805141993031002
A27: I. | B27: Tiba di | C27: : | D27: Bandung | G27: Berangkat dari | H27: =D27 -> Bandung
B28: Pada tanggal | C28: : | D28: 9 September 2024 | G28: Tujuan ke | H28: Jakarta
G29: Pada tanggal | H29: 13 September 2024
B30: Kepala | C30: : | D30: =D15 -> 0 | G30: Kepala | H30: =D30 -> 0
B33: =B17 -> 0 | G33: =B33 -> 0
B34: =B18 -> 0 | G34: =B34 -> 0
C35: Palembang
C36: 21 Januari 2026
C38: :
C41: Dodi Oktavianto, S.E. | F41: Dodi Oktavianto, S.E.
C42: 197810032008101001 | F42: 197810032008101001
